<?xml version="1.0" ?>

<robot name="ruka">


    <material name="white">
        <color rgba="1 1 1 1"/>
    </material>

    <material name="red">
        <color rgba="1 0 0 1"/>
    </material>

    <link name="base_link">
        <visual>
          <origin rpy="0 0 0" xyz="0 0 0.015" />
          <geometry>
            <cylinder radius="0.09" length="0.03" />
          </geometry>

        <material name="white"/>
        </visual>

        <collision>
            <origin rpy="0 0 0" xyz="0 0 0.015" />
          <geometry>
            <cylinder radius="0.09" length="0.03" />
          </geometry>
          </collision>
 
    </link>

    <joint name="base_link__link_01" type="revolute">
        <axis xyz="0 0 1"/>

        <safety_controller k_position="100.0" k_velocity="40.0" soft_lower_limit="-2.908" soft_upper_limit="2.908" />

        <limit effort="1000.0" lower="-2.96" upper="2.96" velocity="0.5"/>
        <origin rpy="0 0 0" xyz="0 0 0.03"/>
        <parent link="base_link"/>
        <child link="link_01"/>
        
    </joint>

    <link name="link_01">
        <visual>
            <origin rpy="0 0 0" xyz="0 0 0.016" />
            <geometry>
                <cylinder radius="0.047" length="0.032" />
            </geometry>
            <material name="white"/>
                
        </visual>

        <collision>
            <origin rpy="0 0 0" xyz="0 0 0.016" />
            <geometry>
                <cylinder radius="0.047" length="0.032" />
            </geometry>
          </collision>

        <visual>
            <origin rpy="0 0 0" xyz="-0.0365 0 0.085" />
            <geometry>
                <box size ="0.173 0.148 0.106"/>  
            </geometry>
            
        </visual>

        <collision>
           <origin rpy="0 0 0" xyz="-0.0365 0 0.085" />
            <geometry>
                <box size ="0.173 0.148 0.106"/>  
            </geometry>
          </collision>
 
    </link>

    <joint name="link_01__link_01_red" type="fixed">
        <origin rpy="0 0 0" xyz="0.01 0 0"/>
        <parent link="link_01"/>
        <child link="link_01_red"/>
    </joint>

    <link name="link_01_red">
        <visual>
            <origin rpy="0 0 0" xyz="0 0.088 0.1115" />
            <geometry>
                <box size ="0.08 0.028 0.135"/>  
            </geometry>
            <material name="red"/>
            
        </visual>

        <collision>
            <origin rpy="0 0 0" xyz="0 0.088 0.1115" />
            <geometry>
                <box size ="0.08 0.028 0.135"/>  
            </geometry>
          </collision>

        <visual>
            <origin rpy="0 0 0" xyz="0 -0.088 0.1115" />
            <geometry>
                <box size ="0.08 0.028 0.135"/>  
            </geometry>

        </visual>

        <collision>
            <origin rpy="0 0 0" xyz="0 -0.088 0.1115" />
            <geometry>
                <box size ="0.08 0.028 0.135"/>  
            </geometry>
          </collision>

        <visual>
            <origin rpy="1.57 0 0" xyz="0 -0.088 0.179" />
            <geometry>
                <cylinder radius="0.04" length="0.028"/>  
            </geometry>

        </visual>

        <collision>
           <origin rpy="1.57 0 0" xyz="0 -0.088 0.179" />
            <geometry>
                <cylinder radius="0.04" length="0.028"/>  
            </geometry>
          </collision>

        <visual>
            <origin rpy="1.57 0 0" xyz="0 0.088 0.179" />
            <geometry>
                <cylinder radius="0.04" length="0.028"/>  
            </geometry>

        </visual>

        <collision>
           <origin rpy="1.57 0 0" xyz="0 0.088 0.179" />
            <geometry>
                <cylinder radius="0.04" length="0.028"/>  
            </geometry>
          </collision>
    </link>

    <joint name="link_01__link_02" type="revolute">
        <axis xyz="0 0 1"/>

        <safety_controller k_position="100.0" k_velocity="40.0" soft_lower_limit="-3.518" soft_upper_limit="-0.052" />

        <limit effort="1000.0" lower="-3.57" upper="0" velocity="0.5"/>
        <origin rpy="1.57 -1.57 0" xyz="0.01 0 0.179"/>   <!-- origin rpy="1.57 0 0"-->
        <parent link="link_01"/>
    
        <child link="link_02"/>
    </joint> 

    <link name="link_02">

        <visual>
            <origin rpy="0 0 0" xyz="0 0 0" />
            <geometry>
                <cylinder radius="0.038" length="0.148"/>  
            </geometry>
            <material name="white"/>

        </visual>

        <collision>
             <origin rpy="0 0 0" xyz="0 0 0" />
            <geometry>
                <cylinder radius="0.038" length="0.148"/>  
            </geometry>
          </collision>

        <visual>
            <origin rpy="0 0 0" xyz="0 0.06775 0" />
            <geometry>
                <box size ="0.076 0.1355 0.116"/>  
            </geometry>
            <material name="white"/>
               
        </visual>

        <collision>
          <origin rpy="0 0 0" xyz="0 0.06775 0" />
            <geometry>
                <box size ="0.076 0.1355 0.116"/>  
            </geometry>
          </collision>

        <visual>
            <origin rpy="0 1.57 0" xyz="0 0.14 0.055" />
            <geometry>
                <box size ="0.006 0.28 0.076"/>  
            </geometry>
            <material name="white"/>
               
        </visual>

        <collision>
            <origin rpy="0 1.57 0" xyz="0 0.14 0.055" />
            <geometry>
                <box size ="0.006 0.28 0.076"/>  
            </geometry>
          </collision>

        <visual>
            <origin rpy="0 1.57 0" xyz="0 0.14 -0.055" />
            <geometry>
                <box size ="0.006 0.28 0.076"/>  
            </geometry>
            <material name="white"/>
               
        </visual>

        <collision>
            <origin rpy="0 1.57 0" xyz="0 0.14 -0.055" />
            <geometry>
                <box size ="0.006 0.28 0.076"/>  
            </geometry>
          </collision>

        <visual>
            <origin rpy="0 0 0" xyz="0 0.28 -0.055" />
            <geometry>
                <cylinder radius="0.038" length="0.006"/>    
            </geometry>
            <material name="white"/>
               
        </visual>

        <collision>
            <origin rpy="0 0 0" xyz="0 0.28 -0.055" />
            <geometry>
                <cylinder radius="0.038" length="0.006"/>    
            </geometry>
          </collision>

        <visual>
            <origin rpy="0 0 0" xyz="0 0.28 0.055" />
            <geometry>
                <cylinder radius="0.038" length="0.006"/>    
            </geometry>
            <material name="white"/>
               
        </visual>

        <collision>
            <origin rpy="0 0 0" xyz="0 0.28 0.055" />
            <geometry>
                <cylinder radius="0.038" length="0.006"/>    
            </geometry>
          </collision>

    </link>

    <joint name="link_02__link_02_red" type="fixed">
        <origin rpy="0 0 0" xyz="0 0.181 0"/>
        <parent link="link_02"/>
        <child link="link_02_red"/>
    </joint>

    <link name="link_02_red">
        <visual>
            <origin rpy="0 0 0" xyz="0 0 0.0705" />
            <geometry>
                <box size ="0.076 0.198 0.025"/>  
            </geometry>
            <material name="red"/>
            
        </visual>

        <collision>
            <origin rpy="0 0 0" xyz="0 0 0.0705" />
            <geometry>
                <box size ="0.076 0.198 0.025"/>  
            </geometry>
          </collision>

        <visual>
            <origin rpy="0 0 0" xyz="0 0 -0.0705" />
            <geometry>
                <box size ="0.076 0.198 0.025"/>  
            </geometry>
    
        </visual>

        <collision>
            <origin rpy="0 0 0" xyz="0 0 -0.0705" />
            <geometry>
                <box size ="0.076 0.198 0.025"/>  
            </geometry>
          </collision>

        <visual>
            <origin rpy="0 0 0" xyz="0 -0.099 0.0705" />
            <geometry>
                <cylinder radius="0.038" length="0.025"/>  
            </geometry>

        </visual>

        <collision>
            <origin rpy="0 0 0" xyz="0 -0.099 0.0705" />
            <geometry>
                <cylinder radius="0.038" length="0.025"/>  
            </geometry>

          </collision>

        <visual>
            <origin rpy="0 0 0" xyz="0 0.099 0.0705" />
            <geometry>
                <cylinder radius="0.038" length="0.025"/>  
            </geometry>

        </visual>

        <collision>
            <origin rpy="0 0 0" xyz="0 0.099 0.0705" />
            <geometry>
                <cylinder radius="0.038" length="0.025"/>  
            </geometry>
          </collision>

        <visual>
            <origin rpy="0 0 0" xyz="0 -0.099 -0.0705" />
            <geometry>
                <cylinder radius="0.038" length="0.025"/>  
            </geometry>

        </visual>

        <collision>
            <origin rpy="0 0 0" xyz="0 -0.099 -0.0705" />
            <geometry>
                <cylinder radius="0.038" length="0.025"/>  
            </geometry>
          </collision>

        <visual>
            <origin rpy="0 0 0" xyz="0 0.099 -0.0705" />
            <geometry>
                <cylinder radius="0.038" length="0.025"/>  
            </geometry>

        </visual>

        <collision>
             <origin rpy="0 0 0" xyz="0 0.099 -0.0705" />
            <geometry>
                <cylinder radius="0.038" length="0.025"/>  
            </geometry>

          </collision>

    </link>

    <joint name="link_02__link_03" type="revolute">
        <axis xyz="0 0 1"/>

        <safety_controller k_position="100.0" k_velocity="40.0" soft_lower_limit="0.067" soft_upper_limit="5.178" />

        <limit effort="1000.0" lower="0.035" upper="5.23" velocity="0.5"/>
        <origin rpy="0 0 0.0175" xyz="0 0.28 0"/> 
        <!-- !!!!!!!!!!!!!!!!!!!!! /> -->
        <parent link="link_02"/>
        <child link="link_03"/>
    </joint>

    <link name="link_03">
        <visual>
            <origin rpy="0 0 0" xyz="0 0 0" />
            <geometry>
                <cylinder radius="0.019" length="0.104" />
            </geometry>
            <material name="white"/>
        </visual>

        <collision>
            <origin rpy="0 0 0" xyz="0 0 0" />
            <geometry>
                <cylinder radius="0.019" length="0.104" />
            </geometry>
          </collision>

        <visual>
            <origin rpy="0 0 0" xyz="0.04 0 0" />
            <geometry>
                <box size ="0.120 0.090 0.08"/>  
            </geometry>
        
        </visual>  

        <collision>
            <origin rpy="0 0 0" xyz="0.04 0 0" />
            <geometry>
                <box size ="0.120 0.090 0.08"/>  
            </geometry>
          </collision>

    </link>

    <joint name="link_03__link_03_red" type="fixed">
        <origin rpy="0 0 0" xyz="0.04 0 0"/>
        <parent link="link_03"/>
        <child link="link_03_red"/>
    </joint>


    <link name="link_03_red">

       <visual>
            <origin rpy="0 0 0" xyz="0 0.05 0" />
            <geometry>
                <box size ="0.120 0.020 0.08"/>  
            </geometry>
            <material name="red"/>
            
        </visual>

        <collision>
           <origin rpy="0 0 0" xyz="0 0.05 0" />
            <geometry>
                <box size ="0.120 0.020 0.08"/>  
            </geometry>
          </collision>

        <visual>
            <origin rpy="0 0 0" xyz="0 -0.05 0" />
            <geometry>
                <box size ="0.120 0.020 0.08"/>  
            </geometry>
            <material name="red"/>
            
        </visual>

        <collision>
            <origin rpy="0 0 0" xyz="0 -0.05 0" />
            <geometry>
                <box size ="0.120 0.020 0.08"/>  
            </geometry>
          </collision>

    </link>

    <joint name="link_03__link_04" type="revolute">
        <axis xyz="0 0 1"/>

        <safety_controller k_position="100.0" k_velocity="40.0" soft_lower_limit="-2.818" soft_upper_limit="2.818" />

        <limit effort="1000.0" lower="-2.87" upper="2.87" velocity="0.5"/>
        <origin rpy="1.57 0 0" xyz="0.068 0 0"/>
        <parent link="link_03"/>
        <child link="link_04"/>
    </joint>

    <link name="link_04">
        <visual>
            <origin rpy="0 0 0" xyz="0 0 0.0455" />
            <geometry>
                <cylinder radius="0.018" length="0.091" />
            </geometry>

            <material name="white"/>
        
        </visual>

        <collision>
             <origin rpy="0 0 0" xyz="0 0 0.0455" />
            <geometry>
                <cylinder radius="0.018" length="0.091" />
            </geometry>

          </collision>

        <visual>
            <origin rpy="0 0 0" xyz="0 0 0.135" />
            <geometry>
                <box size ="0.06 0.078 0.088"/>  
            </geometry>
            
        </visual>

        <collision>
            <origin rpy="0 0 0" xyz="0 0 0.135" />
            <geometry>
                <box size ="0.06 0.078 0.088"/>  
            </geometry>
          </collision>

        <visual>
            <origin rpy="0 0 0" xyz="0 0.042 0.181" />
            <geometry>
                <box size ="0.06 0.006 0.18"/>  
            </geometry>
            
        </visual>

        <collision>
            <origin rpy="0 0 0" xyz="0 0.042 0.181" />
            <geometry>
                <box size ="0.06 0.006 0.18"/>  
            </geometry>
          </collision>

        <visual>
            <origin rpy="0 0 0" xyz="0 -0.042 0.181" />
            <geometry>
                <box size ="0.06 0.006 0.18"/>  
            </geometry>
            
        </visual>

        <collision>
            <origin rpy="0 0 0" xyz="0 -0.042 0.181" />
            <geometry>
                <box size ="0.06 0.006 0.18"/>  
            </geometry>
          </collision>

        <visual>
            <origin rpy="1.57 0 0" xyz="0 0.042 0.271" />
            <geometry>
                <cylinder radius="0.03" length="0.006" />
            </geometry>
        
        </visual>

        <collision>
            <origin rpy="1.57 0 0" xyz="0 0.042 0.271" />
            <geometry>
                <cylinder radius="0.03" length="0.006" />
            </geometry>
          </collision>

        <visual>
            <origin rpy="1.57 0 0" xyz="0 -0.042 0.271" />
            <geometry>
                <cylinder radius="0.03" length="0.006" />
            </geometry>

            <material name="white"/>
        
        </visual>

        <collision>
            <origin rpy="1.57 0 0" xyz="0 -0.042 0.271" />
            <geometry>
                <cylinder radius="0.03" length="0.006" />
            </geometry>
          </collision>

    </link>

    <joint name="link_04__link_04_red" type="fixed">
        <origin rpy="0 0 0" xyz="0 0 0.181"/>
        <parent link="link_04"/>
        <child link="link_04_red"/>
    </joint>

    <link name="link_04_red">

       <visual>
            <origin rpy="0 1.57 0" xyz="0 0.055 0" />
            <geometry>
                <box size ="0.18 0.020 0.06"/>  
            </geometry>
            <material name="red"/>
            
        </visual>

        <collision>
            <origin rpy="0 1.57 0" xyz="0 0.055 0" />
            <geometry>
                <box size ="0.18 0.020 0.06"/>  
            </geometry>
          </collision>

        <visual>
            <origin rpy="0 1.57 0" xyz="0 -0.055 0" />
            <geometry>
                <box size ="0.18 0.020 0.06"/>  
            </geometry>
            <material name="red"/>
            
        </visual>

        <collision>
            <origin rpy="0 1.57 0" xyz="0 -0.055 0" />
            <geometry>
                <box size ="0.18 0.020 0.06"/>  
            </geometry>
          </collision>

        <visual>
            <origin rpy="1.57 0 0" xyz="0 -0.055 0.09" />
            <geometry>
                <cylinder radius="0.03" length="0.02" />
            </geometry>

        </visual>

        <collision>
            <origin rpy="1.57 0 0" xyz="0 -0.055 0.09" />
            <geometry>
                <cylinder radius="0.03" length="0.02" />
            </geometry>
          </collision>

        <visual>
            <origin rpy="1.57 0 0" xyz="0 0.055 0.09" />
            <geometry>
                <cylinder radius="0.03" length="0.02" />
            </geometry>

        </visual>

        <collision>
            <origin rpy="1.57 0 0" xyz="0 0.055 0.09" />
            <geometry>
                <cylinder radius="0.03" length="0.02" />
            </geometry>
          </collision>

    </link>

    <joint name="link_04__link_05" type="revolute">
        <axis xyz="0 0 1"/>

        <safety_controller k_position="100.0" k_velocity="40.0" soft_lower_limit="-2.388" soft_upper_limit="2.388" />

        <limit effort="1000.0" lower="-2.44" upper="2.44" velocity="0.5"/>
        <origin rpy="-1.57 0 0" xyz="0 0 0.271"/>
        <parent link="link_04"/>
        <child link="link_05"/>
    </joint>

    <link name="link_05">
        <visual>
            <origin rpy="0 0 0" xyz="0 0 0" />
            <geometry>
                <cylinder radius="0.0175" length="0.078" />
            </geometry>

            <material name="white"/>
        </visual>

        <collision>
            <origin rpy="0 0 0" xyz="0 0 0" />
            <geometry>
                <cylinder radius="0.0175" length="0.078" />
            </geometry>
          </collision>

        <visual>
            <origin rpy="0 0 0" xyz="0 0 0.0355" />
            <geometry>
                <box size ="0.055 0.1 0.007"/>  
            </geometry>
               
        </visual>

        <collision>
            <origin rpy="0 0 0" xyz="0 0 0.0355" />
            <geometry>
                <box size ="0.055 0.1 0.007"/>  
            </geometry>
          </collision>

        <visual>
            <origin rpy="0 0 0" xyz="0 0 -0.0355" />
            <geometry>
                <box size ="0.055 0.1 0.007"/>  
            </geometry>
            <material name="white"/>
            
        </visual>

        <collision>
            <origin rpy="0 0 0" xyz="0 0 -0.0355" />
            <geometry>
                <box size ="0.055 0.1 0.007"/>  
            </geometry>
          </collision>

        <visual>
            <origin rpy="0 0 0" xyz="0 -0.0465 0" />
            <geometry>
                <box size ="0.055 0.007 0.078"/>  
            </geometry>
            <material name="white"/>
            
        </visual>

        <collision>
            <origin rpy="0 0 0" xyz="0 -0.0465 0" />
            <geometry>
                <box size ="0.055 0.007 0.078"/>  
            </geometry>
          </collision>
 
    </link> 

    <joint name="link_05__link_05_red" type="fixed">
        <origin rpy="0 0 0" xyz="0 0.05 0"/>
        <parent link="link_05"/>
        <child link="link_05_red"/>
    </joint>

    <link name="link_05_red">

       <visual>
            <origin rpy="0 0 0" xyz="0 -0.00075 0" />
            <geometry>
                <box size ="0.055 0.0015 0.078"/>  
            </geometry>
            <material name="red"/>
            
        </visual>

        <collision>
            <origin rpy="0 0 0" xyz="0 -0.00075 0" />
            <geometry>
                <box size ="0.055 0.0015 0.078"/>  
            </geometry>
          </collision>

        <visual>
            <origin rpy="0 0 0" xyz="0.02675 -0.05 0" />
            <geometry>
                <box size ="0.0015 0.1 0.078"/>  
            </geometry>
            <material name="red"/>
            
        </visual>

        <collision>
            <origin rpy="0 0 0" xyz="0.02675 -0.05 0" />
            <geometry>
                <box size ="0.0015 0.1 0.078"/>  
            </geometry>
          </collision>

        <visual>
            <origin rpy="0 0 0" xyz="-0.02675 -0.05 0" />
            <geometry>
                <box size ="0.0015 0.1 0.078"/>  
            </geometry>
            <material name="red"/>
            
        </visual>

        <collision>
            <origin rpy="0 0 0" xyz="-0.02675 -0.05 0" />
            <geometry>
                <box size ="0.0015 0.1 0.078"/>  
            </geometry>
          </collision>

    </link>

    <joint name="link_05__link_06" type="revolute">
        <axis xyz="0 0 1"/>

        <safety_controller k_position="100.0" k_velocity="40.0" soft_lower_limit="-3.12" soft_upper_limit="3.12" />

        <limit effort="1000.0" lower="-3.14" upper="3.14" velocity="0.5"/>
        <origin rpy="1.57 0 0" xyz="0 -0.0766 0"/>
        <parent link="link_05"/>
        <child link="link_06"/>
    </joint>

    <link name="link_06">
        <visual>
            <origin rpy="0 0 0" xyz="0 0 -0.0159" />
            <geometry>
                <cylinder radius="0.0095" length="0.0168" />
            </geometry>
            <material name="white"/>
        </visual>

        <collision>
            <origin rpy="0 0 0" xyz="0 0 -0.0159" />
            <geometry>
                <cylinder radius="0.0095" length="0.0168" />
            </geometry>

          </collision>

        <visual>
            <origin rpy="0 0 0" xyz="0 0 -0.005" />
            <geometry>
                <cylinder radius="0.024" length="0.005" />
            </geometry>
            <material name="white"/>
            
        </visual>

        <collision>
            <origin rpy="0 0 0" xyz="0 0 -0.005" />
            <geometry>
                <cylinder radius="0.024" length="0.005" />
            </geometry>

          </collision>
    </link>

<!-- ////////////////////////////////////////////// -->

    <joint name="link_06__link_hand_1" type="fixed">
        <origin rpy="0 0 0" xyz="0 0 0"/>
        <parent link="link_06"/>
        <child link="link_hand_1"/>
    </joint>

    <link name="link_hand_1">
        <visual>
            <origin rpy="0 0 0" xyz="0 0 0.01" />
            <geometry>
                <cylinder radius="0.012" length="0.02" />
            </geometry>
            <material name="white"/>
        </visual>

        <collision>
            <origin rpy="0 0 0" xyz="0 0 0.01" />
            <geometry>
                <cylinder radius="0.010" length="0.01" />
            </geometry>

          </collision>

        <visual>
            <origin rpy="1.57 0 0" xyz="0.0061 0 0.02" />
            <geometry>
                <cylinder radius="0.006" length="0.02" />
            </geometry>
            <material name="white"/>
            
        </visual>

        <!-- <collision>
             <origin rpy="1.57 0 0" xyz="0.0025 0 0.02" />
            <geometry>
                <cylinder radius="0." length="0.02" />
            </geometry>
          </collision> -->


        <visual>
            <origin rpy="1.57 0 0" xyz="-0.0061 0 0.02" />
            <geometry>
                <cylinder radius="0.006" length="0.02" />
            </geometry>
            <material name="white"/>
            
        </visual>

        <!-- <collision>
            <origin rpy="1.57 0 0" xyz="-0.0025 0 0.02" />
            <geometry>
                <cylinder radius="0.0049" length="0.02" />
            </geometry>
          </collision> -->
    </link>
    
    <joint name="link_hand_1__up_finger" type="revolute">
        <axis xyz="0 1 0"/>

        <safety_controller k_position="100.0" k_velocity="40.0" soft_lower_limit="0" soft_upper_limit="1.57" />

        <limit effort="1000.0" lower="0" upper="1.57" velocity="0.5"/>
        <origin rpy="0 0 0" xyz="0 0 0.02"/>
        <parent link="link_hand_1"/>
        <child link="up_finger"/>
    </joint> 

    <link name ="up_finger">
        <visual>
            <origin rpy="0 0 0" xyz="0.006 0 0.025" />
            <geometry>
                <box size ="0.011 0.012 0.05"/>  
            </geometry>
            <material name="white"/>
               
        </visual>

        <collision>
            <origin rpy="0 0 0" xyz="0.006 0 0.025" />
            <geometry>
                <box size ="0.011 0.011 0.05"/>  
            </geometry>
          </collision>

          <!-- <visual>
            <origin rpy="0 0 0" xyz="-0.006 0 0.025" />
            <geometry>
                <box size ="0.011 0.012 0.05"/>  
            </geometry>
            <material name="white"/>
               
        </visual>

        <collision>
            <origin rpy="0 0 0" xyz="-0.006 0 0.025" />
            <geometry>
                <box size ="0.011 0.011 0.05"/>  
            </geometry>
          </collision> -->
    </link>

    <joint name="up_finger__up_finger_mim" type="revolute">
        <axis xyz="1 0 0"/>
        <limit effort="1000.0" lower="-3.14" upper="3.14" velocity="0.5"/>
        <origin rpy="0 0 1.57" xyz="-0.006 0 0.05"/>
        <parent link="down_finger"/>
        <child link="down_finger_mim"/>
        <mimic joint="link_hand_1__up_finger" multiplier="1" offset="0" />
    </joint>



    <link name="up_finger_mim">
        <visual>
            <origin rpy="0 1.57 0" xyz="0 0 0" />
            <geometry>
                <cylinder radius="0.006" length="0.011" />
            </geometry>
            <material name="white"/>
        </visual>

        <!-- <collision>
            <origin rpy="1.57 0 0" xyz="0 0 0.01" />
            <geometry>
                <cylinder radius="0.012" length="0.011" />
            </geometry>
            <material name="white"/>

          </collision> -->

         <visual>
            <origin rpy="0 0 0" xyz="0 0 0.025" />
            <geometry>
                <box size ="0.011 0.012 0.05"/>  
            </geometry>
            <material name="white"/>
               
        </visual>

        <collision>
            <origin rpy="0 0 0" xyz="0 0 0.025" />
            <geometry>
                <box size ="0.011 0.011 0.047"/>  
            </geometry>
          </collision>

    </link>




    <joint name="up_finger__down_finger_mim" type="revolute">
        <axis xyz="1 0 0"/>
        <limit effort="1000.0" lower="-3.14" upper="3.14" velocity="0.5"/>
        <origin rpy="0 0 1.57" xyz="0.006 0 0.05"/>
        <parent link="up_finger"/>
        <child link="up_finger_mim"/>
        <mimic joint="link_hand_1__up_finger" multiplier="-1" offset="0" />
    </joint>



    <link name="down_finger_mim">
        <visual>
            <origin rpy="0 1.57 0" xyz="0 0 0" />
            <geometry>
                <cylinder radius="0.006" length="0.011" />
            </geometry>
            <material name="white"/>
        </visual>

        <!-- <collision>
            <origin rpy="1.57 0 0" xyz="0 0 0.01" />
            <geometry>
                <cylinder radius="0.012" length="0.011" />
            </geometry>
            <material name="white"/>

          </collision> -->

         <visual>
            <origin rpy="0 0 0" xyz="0 0 0.025" />
            <geometry>
                <box size ="0.011 0.012 0.05"/>  
            </geometry>
            <material name="white"/>
               
        </visual>

        <collision>
            <origin rpy="0 0 0" xyz="0 0 0.025" />
            <geometry>
                <box size ="0.011 0.011 0.04"/>  
            </geometry>
          </collision>

    </link>


    <joint name="link_hand_1__down_finger" type="revolute">
        <axis xyz="0 1 0"/>
        <limit effort="1000.0" lower="-3.14" upper="3.14" velocity="0.5"/>
        <origin rpy="0 0 0" xyz="0 0 0.02"/>
        <parent link="link_hand_1"/>
        <child link="down_finger"/>
        <mimic joint="link_hand_1__up_finger" multiplier="-1" offset="0" />
    </joint>


     <link name ="down_finger">
        <!-- <visual>
            <origin rpy="0 0 0" xyz="0.006 0 0.025" />
            <geometry>
                <box size ="0.011 0.012 0.05"/>  
            </geometry>
            <material name="white"/>
               
        </visual>

        <collision>
            <origin rpy="0 0 0" xyz="0.006 0 0.025" />
            <geometry>
                <box size ="0.011 0.011 0.05"/>  
            </geometry>
          </collision> -->

          <visual>
            <origin rpy="0 0 0" xyz="-0.006 0 0.025" />
            <geometry>
                <box size ="0.011 0.012 0.05"/>  
            </geometry>
            <material name="white"/>
               
        </visual>

        <collision>
            <origin rpy="0 0 0" xyz="-0.006 0 0.025" />
            <geometry>
                <box size ="0.011 0.011 0.047"/>  
            </geometry>
          </collision>
    </link>



</robot>
