<?xml version="1.0" ?>

<robot name="ruka_gz">

    <link name="world"/>

    <joint name="ruka_joint_world" type="fixed">
        <parent link="world"/>
        <child link="base_link"/>
        <origin rpy="0 0 0" xyz="0 0 0"/>
    </joint>

    <link name="base_link">

        <inertial>
            <mass value="2.92"/>
            <origin rpy="0 0 0" xyz="-0.025566 -2.88e-05 0.057332"/>
            <inertia ixx="0.00782229414331" ixy="-1.56191622996e-05" ixz="-0.00126005738123" iyy="0.0109027971813" iyz="1.08233858202e-05" izz="0.0102355503949"/>
        </inertial>

        <visual>
          <origin rpy="0 0 0" xyz="0 0 0.015" />
          <geometry>
            <cylinder radius="0.09" length="0.03" />
          </geometry>

        </visual>

        <collision>
            <origin rpy="0 0 0" xyz="0 0 0.015" />
          <geometry>
            <cylinder radius="0.09" length="0.03" />
          </geometry>
          </collision>
 
    </link>

    <joint name="base_link__link_01" type="revolute">
        <axis xyz="0 0 1"/>

        <safety_controller k_position="100.0" k_velocity="40.0" soft_lower_limit="-2.908" soft_upper_limit="2.908" />

        <limit effort="1000.0" lower="-2.96" upper="2.96" velocity="0.5"/>
        <origin rpy="0 0 0" xyz="0 0 0.03"/>
        <parent link="base_link"/>
        <child link="link_01"/>
        
    </joint>

    <link name="link_01">

        <inertial>
            <mass value="2.74"/>
            <origin rpy="0 0 0" xyz="0 -0.0324958 -0.0675818"/>
            <inertia ixx="0.0180416958283" ixy="0.0" ixz="0.0" iyy="0.0159136071891" iyz="0.0046758424612" izz="0.00620690827127"/>
        </inertial>
   
        <visual>
            <origin rpy="0 0 0" xyz="0 0 0.016" />
            <geometry>
                <cylinder radius="0.047" length="0.032" />
            </geometry>
     
                
        </visual>

        <collision>
            <origin rpy="0 0 0" xyz="0 0 0.016" />
            <geometry>
                <cylinder radius="0.047" length="0.032" />
            </geometry>
          </collision>
 
    </link>



    <joint name="link_01__link_02" type="revolute">
        <axis xyz="0 0 1"/>

        <safety_controller k_position="100.0" k_velocity="40.0" soft_lower_limit="-3.518" soft_upper_limit="-0.052" />

        <limit effort="1000.0" lower="-3.57" upper="0" velocity="0.5"/>
        <origin rpy="1.57 -1.57 0" xyz="0.01 0 0.179"/>   <!-- origin rpy="1.57 0 0"-->
        <parent link="link_01"/>
    
        <child link="link_02"/>
    </joint> 

    <link name="link_02">
        <inertial>
            <mass value="2.74"/>
            <origin rpy="0 0 0" xyz="0 -0.06861 0.0322285"/>
            <inertia ixx="0.0182856182281" ixy="0.0" ixz="0.0" iyy="0.00621358421175" iyz="-0.00472844221905" izz="0.0161514346309"/>
        </inertial>

        <visual>
            <origin rpy="0 0 0" xyz="0 0 0" />
            <geometry>
                <cylinder radius="0.038" length="0.148"/>  
            </geometry>
            
        </visual>

        <collision>
             <origin rpy="0 0 0" xyz="0 0 0" />
            <geometry>
                <cylinder radius="0.038" length="0.148"/>  
            </geometry>
          </collision>

       

    </link>

   

    <joint name="link_02__link_03" type="revolute">
        <axis xyz="0 0 1"/>

        <safety_controller k_position="100.0" k_velocity="40.0" soft_lower_limit="0.067" soft_upper_limit="5.178" />

        <limit effort="1000.0" lower="0.035" upper="5.23" velocity="0.5"/>
        <origin rpy="0 0 0.0175" xyz="0 0.28 0"/> 
        <!-- !!!!!!!!!!!!!!!!!!!!! /> -->
        <parent link="link_02"/>
        <child link="link_03"/>
    </joint>

    <link name="link_03">
        <inertial>
            <mass value="2.38"/>
            <origin rpy="0 0 0" xyz="0.0469893 0.0316374 -0.031704"/>
            <inertia ixx="0.00771376630908" ixy="-0.00248490625138" ixz="-0.00332147581033" iyy="0.00989108008727" iyz="-0.00217796151484" izz="0.00811723558464"/>
        </inertial>
        <visual>
            <origin rpy="0 0 0" xyz="0 0 0" />
            <geometry>
                <cylinder radius="0.019" length="0.104" />
            </geometry>
          
        </visual>

        <collision>
            <origin rpy="0 0 0" xyz="0 0 0" />
            <geometry>
                <cylinder radius="0.019" length="0.104" />
            </geometry>
          </collision>

       
    </link>

  

    <joint name="link_03__link_04" type="revolute">
        <axis xyz="0 0 1"/>

        <safety_controller k_position="100.0" k_velocity="40.0" soft_lower_limit="-2.818" soft_upper_limit="2.818" />

        <limit effort="1000.0" lower="-2.87" upper="2.87" velocity="0.5"/>
        <origin rpy="1.57 0 0" xyz="0.068 0 0"/>
        <parent link="link_03"/>
        <child link="link_04"/>
    </joint>

    <link name="link_04">

        <inertial>
            <mass value="2.38"/>
            <origin rpy="0 0 0" xyz="-0.0360446 0.0336853 0.031882"/>
            <inertia ixx="0.00799663881132" ixy="0.00347095570217" ixz="-0.00241222942995" iyy="0.00825390705278" iyz="0.00235774044121" izz="0.0102515004345"/>
        </inertial>
        <visual>
            <origin rpy="0 0 0" xyz="0 0 0.0455" />
            <geometry>
                <cylinder radius="0.018" length="0.091" />
            </geometry>


        </visual>

        <collision>
             <origin rpy="0 0 0" xyz="0 0 0.0455" />
            <geometry>
                <cylinder radius="0.018" length="0.091" />
            </geometry>

          </collision>

       
    </link>

   
    <joint name="link_04__link_05" type="revolute">
        <axis xyz="0 0 1"/>

        <safety_controller k_position="100.0" k_velocity="40.0" soft_lower_limit="-2.388" soft_upper_limit="2.388" />

        <limit effort="1000.0" lower="-2.44" upper="2.44" velocity="0.5"/>
        <origin rpy="-1.57 0 0" xyz="0 0 0.271"/>
        <parent link="link_04"/>
        <child link="link_05"/>
    </joint>

    <link name="link_05">
        <inertial>
            <mass value="2.74"/>
            <origin rpy="0 0 0" xyz="0 0.0610427 -0.104176"/>
            <inertia ixx="0.030371374513" ixy="6.50283587108e-07" ixz="-1.05129179916e-05" iyy="0.0288752887402" iyz="-0.00775653445787" izz="0.00444134056164"/>
        </inertial>
        <visual>
            <origin rpy="0 0 0" xyz="0 0 0" />
            <geometry>
                <cylinder radius="0.0175" length="0.078" />
            </geometry>

          
        </visual>

        <collision>
            <origin rpy="0 0 0" xyz="0 0 0" />
            <geometry>
                <cylinder radius="0.0175" length="0.078" />
            </geometry>
          </collision>
 
    </link> 

  

    <joint name="link_05__link_06" type="revolute">
        <axis xyz="0 0 1"/>

        <safety_controller k_position="100.0" k_velocity="40.0" soft_lower_limit="-3.12" soft_upper_limit="3.12" />

        <limit effort="1000.0" lower="-3.14" upper="3.14" velocity="0.5"/>
        <origin rpy="1.57 0 0" xyz="0 -0.0766 0"/>
        <parent link="link_05"/>
        <child link="link_06"/>
    </joint>

    <link name="link_06">

        <inertial>
            <mass value="1.55"/>
            <origin rpy="0 0 0" xyz="0.0510509 0.009108 0.0106343"/>
            <inertia ixx="0.00303336450376" ixy="-0.000437276865508" ixz="0.000629257294877" iyy="0.00404479911567" iyz="0.000130472021025" izz="0.00558234286039"/>
        </inertial>
        <visual>
            <origin rpy="0 0 0" xyz="0 0 -0.0159" />
            <geometry>
                <cylinder radius="0.0095" length="0.0168" />
            </geometry>
        </visual>

        <collision>
            <origin rpy="0 0 0" xyz="0 0 -0.0159" />
            <geometry>
                <cylinder radius="0.0095" length="0.0168" />
            </geometry>

          </collision>

     
    </link>

   
    <gazebo reference="base_link">
      <material>Gazebo/Orange</material>
    </gazebo>

    <gazebo reference="link_01">
      <material>Gazebo/Orange</material>
    </gazebo>

    <gazebo reference="link_02">
      <material>Gazebo/Orange</material>
    </gazebo>

    <gazebo reference="link_03">
      <material>Gazebo/Orange</material>
    </gazebo>

    <gazebo reference="link_04">
      <material>Gazebo/Orange</material>
    </gazebo>

    <gazebo reference="link_05">
      <material>Gazebo/Orange</material>
    </gazebo>

    <gazebo reference="link_06">
      <material>Gazebo/Orange</material>
    </gazebo>

</robot>
